{"session_id": "devin-8146e4f29f9f49f290bc59ec9e7de6ad", "issues": [{"file": "etebase_fastapi/routers/authentication.py", "line": 60, "description": "Potential AttributeError: UserOut.from_orm accesses obj.userinfo without checking if the attribute exists"}, {"file": "etebase_fastapi/routers/authentication.py", "line": 141, "description": "Potential AttributeError: save_changed_password accesses user.userinfo without checking if the attribute exists"}, {"file": "etebase_fastapi/routers/authentication.py", "line": 154, "description": "Potential AttributeError: validate_login_request accesses user.userinfo.salt without checking if userinfo exists"}, {"file": "etebase_fastapi/routers/authentication.py", "line": 168, "description": "Potential AttributeError: validate_login_request accesses user.userinfo.loginPubkey without checking if userinfo exists"}, {"file": "etebase_fastapi/routers/authentication.py", "line": 182, "description": "Potential AttributeError: login_challenge accesses user.userinfo.salt without checking if userinfo exists"}, {"file": "etebase_fastapi/routers/authentication.py", "line": 190, "description": "Potential AttributeError: login_challenge accesses user.userinfo.version without checking if userinfo exists"}, {"file": "etebase_fastapi/routers/authentication.py", "line": 233, "description": "SQL Injection vulnerability: user input (username) is used directly in a database query without proper sanitization"}, {"file": "etebase_fastapi/routers/authentication.py", "line": 170, "description": "Timing attack vulnerability: signature verification doesn't use constant-time comparison"}, {"file": "etebase_fastapi/routers/authentication.py", "line": 248, "description": "Overly broad exception handling: generic Exception catch could mask important errors and provide insufficient error information"}, {"file": "etebase_fastapi/routers/collection.py", "line": 61, "description": "Potential AttributeError: CollectionItemRevisionInOut.from_orm_context accesses obj.chunks_relation without validation"}, {"file": "etebase_fastapi/routers/collection.py", "line": 111, "description": "Potential AttributeError: CollectionOut.from_orm_context accesses obj.members without validation"}, {"file": "etebase_fastapi/routers/collection.py", "line": 250, "description": "Potential AttributeError: has_write_access accesses collection.members without validation"}, {"file": "etebase_fastapi/routers/collection.py", "line": 338, "description": "Potential AttributeError: _create attempts to assign to instance.main_item which may not be a valid attribute"}, {"file": "etebase_fastapi/routers/collection.py", "line": 399, "description": "Potential AttributeError: item_create accesses instance.revisions without validation"}, {"file": "etebase_fastapi/routers/collection.py", "line": 512, "description": "Potential AttributeError: item_revisions accesses item.revisions without validation"}, {"file": "etebase_fastapi/routers/collection.py", "line": 615, "description": "Type error: chunk_save is decorated with sync_to_async but is awaited directly, which could cause runtime errors"}, {"file": "etebase_fastapi/routers/collection.py", "line": 628, "description": "Potential AttributeError: chunk_download accesses collection.chunks without validation"}, {"file": "etebase_fastapi/routers/collection.py", "line": 552, "description": "Potential ValueError: zip function in fetch_updates will fail if data is empty"}, {"file": "etebase_fastapi/routers/collection.py", "line": 305, "description": "Security vulnerability: process_revisions_for_item saves file content without validation, potential for malicious file uploads"}, {"file": "etebase_fastapi/routers/collection.py", "line": 380, "description": "Race condition: item_create uses get_or_create without proper transaction isolation"}, {"file": "etebase_fastapi/routers/invitation.py", "line": 110, "description": "Potential AttributeError: list_common accesses iterator_obj.id without validation"}, {"file": "etebase_fastapi/routers/invitation.py", "line": 204, "description": "Potential AttributeError: outgoing_create accesses collection.members without validation"}, {"file": "etebase_fastapi/routers/invitation.py", "line": 80, "description": "Potential AttributeError: CollectionInvitationOut.from_orm accesses obj.fromMember.user.userinfo.pubkey without validation"}, {"file": "etebase_fastapi/routers/invitation.py", "line": 196, "description": "SQL Injection vulnerability: user input (username) is used in a database query without proper sanitization"}, {"file": "etebase_fastapi/routers/invitation.py", "line": 120, "description": "Potential IndexError: list_common accesses ret_data[-1].uid without checking if result is empty"}, {"file": "etebase_fastapi/routers/invitation.py", "line": 169, "description": "Race condition: incoming_accept doesn't verify invitation state before accepting, could lead to issues if invitation is deleted concurrently"}, {"file": "etebase_fastapi/routers/member.py", "line": 108, "description": "Potential AttributeError: member_leave accesses collection.members without validation"}, {"file": "etebase_fastapi/routers/member.py", "line": 84, "description": "Potential AttributeError: member_delete calls obj.revoke() without checking if the method exists"}, {"file": "etebase_fastapi/routers/member.py", "line": 109, "description": "Potential AttributeError: member_leave calls obj.revoke() without checking if the method exists"}, {"file": "etebase_fastapi/routers/member.py", "line": 70, "description": "Potential TypeError: member_list accesses result without validation that filter_by_stoken_and_limit returned valid data"}, {"file": "etebase_fastapi/routers/websocket.py", "line": 54, "description": "Potential RuntimeError: get_ticket uses redisw.redis without validating it's properly initialized"}, {"file": "etebase_fastapi/routers/websocket.py", "line": 59, "description": "Potential SecurityVulnerability: load_websocket_ticket doesn't validate ticket format before using it"}, {"file": "etebase_fastapi/routers/websocket.py", "line": 71, "description": "Potential DoesNotExist exception: get_websocket_user doesn't handle case where user with given ID doesn't exist"}, {"file": "etebase_fastapi/routers/websocket.py", "line": 84, "description": "Potential NoneType exception: websocket_endpoint passes ticket_model to redis_connector without checking if it's None"}, {"file": "etebase_fastapi/routers/websocket.py", "line": 98, "description": "Potential exception: send_item_updates doesn't handle case where collection doesn't exist or user doesn't have access"}, {"file": "etebase_fastapi/routers/websocket.py", "line": 107, "description": "Potential RuntimeError: redis_connector uses Redis without validating it's properly initialized"}, {"file": "etebase_fastapi/routers/websocket.py", "line": 125, "description": "Race condition: asyncio.wait in producer_handler could lead to unexpected behavior if both tasks complete simultaneously"}]}